(0.001) QUERY = "\n            SELECT name, type FROM sqlite_master\n            WHERE type in ('table', 'view') AND NOT name='sqlite_sequence'\n            ORDER BY name" - PARAMS = (); args=None
(0.000) QUERY = 'SELECT "django_migrations"."app", "django_migrations"."name" FROM "django_migrations"' - PARAMS = (); args=()
Internal Server Error: /
Traceback (most recent call last):
  File "/Users/b1xpc0/anaconda/envs/bondservice/lib/python3.3/site-packages/django/core/handlers/base.py", line 132, in get_response
    response = wrapped_callback(request, *callback_args, **callback_kwargs)
  File "/Users/b1xpc0/anaconda/envs/bondservice/lib/python3.3/site-packages/django/views/decorators/csrf.py", line 58, in wrapped_view
    return view_func(*args, **kwargs)
  File "/Users/b1xpc0/anaconda/envs/bondservice/lib/python3.3/site-packages/django/views/generic/base.py", line 71, in view
    return self.dispatch(request, *args, **kwargs)
  File "/Users/b1xpc0/anaconda/envs/bondservice/lib/python3.3/site-packages/rest_framework/views.py", line 477, in dispatch
    response = self.handle_exception(exc)
  File "/Users/b1xpc0/anaconda/envs/bondservice/lib/python3.3/site-packages/rest_framework/views.py", line 437, in handle_exception
    self.raise_uncaught_exception(exc)
  File "/Users/b1xpc0/anaconda/envs/bondservice/lib/python3.3/site-packages/rest_framework/views.py", line 474, in dispatch
    response = handler(request, *args, **kwargs)
  File "/Users/b1xpc0/anaconda/envs/bondservice/lib/python3.3/site-packages/rest_framework/schemas.py", line 593, in get
    schema = generator.get_schema(request)
  File "/Users/b1xpc0/anaconda/envs/bondservice/lib/python3.3/site-packages/rest_framework/schemas.py", line 242, in get_schema
    links = self.get_links(request)
  File "/Users/b1xpc0/anaconda/envs/bondservice/lib/python3.3/site-packages/rest_framework/schemas.py", line 273, in get_links
    link = self.get_link(path, method, view)
  File "/Users/b1xpc0/anaconda/envs/bondservice/lib/python3.3/site-packages/rest_framework/schemas.py", line 372, in get_link
    fields += self.get_serializer_fields(path, method, view)
  File "/Users/b1xpc0/anaconda/envs/bondservice/lib/python3.3/site-packages/rest_framework/schemas.py", line 488, in get_serializer_fields
    for field in serializer.fields.values():
  File "/Users/b1xpc0/anaconda/envs/bondservice/lib/python3.3/site-packages/rest_framework/serializers.py", line 359, in fields
    for key, value in self.get_fields().items():
  File "/Users/b1xpc0/anaconda/envs/bondservice/lib/python3.3/site-packages/rest_framework/serializers.py", line 1000, in get_fields
    field_name, info, model, depth
  File "/Users/b1xpc0/anaconda/envs/bondservice/lib/python3.3/site-packages/rest_framework/serializers.py", line 1135, in build_field
    return self.build_unknown_field(field_name, model_class)
  File "/Users/b1xpc0/anaconda/envs/bondservice/lib/python3.3/site-packages/rest_framework/serializers.py", line 1242, in build_unknown_field
    (field_name, model_class.__name__)
django.core.exceptions.ImproperlyConfigured: Field name `paymentFrequency` is not valid for model `Bond`.
Internal Server Error: /
Traceback (most recent call last):
  File "/Users/b1xpc0/anaconda/envs/bondservice/lib/python3.3/site-packages/django/core/handlers/base.py", line 132, in get_response
    response = wrapped_callback(request, *callback_args, **callback_kwargs)
  File "/Users/b1xpc0/anaconda/envs/bondservice/lib/python3.3/site-packages/django/views/decorators/csrf.py", line 58, in wrapped_view
    return view_func(*args, **kwargs)
  File "/Users/b1xpc0/anaconda/envs/bondservice/lib/python3.3/site-packages/django/views/generic/base.py", line 71, in view
    return self.dispatch(request, *args, **kwargs)
  File "/Users/b1xpc0/anaconda/envs/bondservice/lib/python3.3/site-packages/rest_framework/views.py", line 477, in dispatch
    response = self.handle_exception(exc)
  File "/Users/b1xpc0/anaconda/envs/bondservice/lib/python3.3/site-packages/rest_framework/views.py", line 437, in handle_exception
    self.raise_uncaught_exception(exc)
  File "/Users/b1xpc0/anaconda/envs/bondservice/lib/python3.3/site-packages/rest_framework/views.py", line 474, in dispatch
    response = handler(request, *args, **kwargs)
  File "/Users/b1xpc0/anaconda/envs/bondservice/lib/python3.3/site-packages/rest_framework/schemas.py", line 593, in get
    schema = generator.get_schema(request)
  File "/Users/b1xpc0/anaconda/envs/bondservice/lib/python3.3/site-packages/rest_framework/schemas.py", line 242, in get_schema
    links = self.get_links(request)
  File "/Users/b1xpc0/anaconda/envs/bondservice/lib/python3.3/site-packages/rest_framework/schemas.py", line 273, in get_links
    link = self.get_link(path, method, view)
  File "/Users/b1xpc0/anaconda/envs/bondservice/lib/python3.3/site-packages/rest_framework/schemas.py", line 372, in get_link
    fields += self.get_serializer_fields(path, method, view)
  File "/Users/b1xpc0/anaconda/envs/bondservice/lib/python3.3/site-packages/rest_framework/schemas.py", line 488, in get_serializer_fields
    for field in serializer.fields.values():
  File "/Users/b1xpc0/anaconda/envs/bondservice/lib/python3.3/site-packages/rest_framework/serializers.py", line 359, in fields
    for key, value in self.get_fields().items():
  File "/Users/b1xpc0/anaconda/envs/bondservice/lib/python3.3/site-packages/rest_framework/serializers.py", line 1000, in get_fields
    field_name, info, model, depth
  File "/Users/b1xpc0/anaconda/envs/bondservice/lib/python3.3/site-packages/rest_framework/serializers.py", line 1135, in build_field
    return self.build_unknown_field(field_name, model_class)
  File "/Users/b1xpc0/anaconda/envs/bondservice/lib/python3.3/site-packages/rest_framework/serializers.py", line 1242, in build_unknown_field
    (field_name, model_class.__name__)
django.core.exceptions.ImproperlyConfigured: Field name `paymentFrequency` is not valid for model `Bond`.
Internal Server Error: /bonds/
Traceback (most recent call last):
  File "/Users/b1xpc0/anaconda/envs/bondservice/lib/python3.3/site-packages/django/core/handlers/base.py", line 132, in get_response
    response = wrapped_callback(request, *callback_args, **callback_kwargs)
  File "/Users/b1xpc0/anaconda/envs/bondservice/lib/python3.3/site-packages/django/views/decorators/csrf.py", line 58, in wrapped_view
    return view_func(*args, **kwargs)
  File "/Users/b1xpc0/anaconda/envs/bondservice/lib/python3.3/site-packages/django/views/generic/base.py", line 71, in view
    return self.dispatch(request, *args, **kwargs)
  File "/Users/b1xpc0/anaconda/envs/bondservice/lib/python3.3/site-packages/rest_framework/views.py", line 477, in dispatch
    response = self.handle_exception(exc)
  File "/Users/b1xpc0/anaconda/envs/bondservice/lib/python3.3/site-packages/rest_framework/views.py", line 437, in handle_exception
    self.raise_uncaught_exception(exc)
  File "/Users/b1xpc0/anaconda/envs/bondservice/lib/python3.3/site-packages/rest_framework/views.py", line 474, in dispatch
    response = handler(request, *args, **kwargs)
  File "/Users/b1xpc0/devops/ref-impl/bondservice_project/bondservice_app/views.py", line 33, in post
    logger.debug(json)
NameError: global name 'logger' is not defined
Internal Server Error: /
Traceback (most recent call last):
  File "/Users/b1xpc0/anaconda/envs/bondservice/lib/python3.3/site-packages/django/core/handlers/base.py", line 132, in get_response
    response = wrapped_callback(request, *callback_args, **callback_kwargs)
  File "/Users/b1xpc0/anaconda/envs/bondservice/lib/python3.3/site-packages/django/views/decorators/csrf.py", line 58, in wrapped_view
    return view_func(*args, **kwargs)
  File "/Users/b1xpc0/anaconda/envs/bondservice/lib/python3.3/site-packages/django/views/generic/base.py", line 71, in view
    return self.dispatch(request, *args, **kwargs)
  File "/Users/b1xpc0/anaconda/envs/bondservice/lib/python3.3/site-packages/rest_framework/views.py", line 477, in dispatch
    response = self.handle_exception(exc)
  File "/Users/b1xpc0/anaconda/envs/bondservice/lib/python3.3/site-packages/rest_framework/views.py", line 437, in handle_exception
    self.raise_uncaught_exception(exc)
  File "/Users/b1xpc0/anaconda/envs/bondservice/lib/python3.3/site-packages/rest_framework/views.py", line 474, in dispatch
    response = handler(request, *args, **kwargs)
  File "/Users/b1xpc0/anaconda/envs/bondservice/lib/python3.3/site-packages/rest_framework/schemas.py", line 593, in get
    schema = generator.get_schema(request)
  File "/Users/b1xpc0/anaconda/envs/bondservice/lib/python3.3/site-packages/rest_framework/schemas.py", line 242, in get_schema
    links = self.get_links(request)
  File "/Users/b1xpc0/anaconda/envs/bondservice/lib/python3.3/site-packages/rest_framework/schemas.py", line 273, in get_links
    link = self.get_link(path, method, view)
  File "/Users/b1xpc0/anaconda/envs/bondservice/lib/python3.3/site-packages/rest_framework/schemas.py", line 372, in get_link
    fields += self.get_serializer_fields(path, method, view)
  File "/Users/b1xpc0/anaconda/envs/bondservice/lib/python3.3/site-packages/rest_framework/schemas.py", line 488, in get_serializer_fields
    for field in serializer.fields.values():
  File "/Users/b1xpc0/anaconda/envs/bondservice/lib/python3.3/site-packages/rest_framework/serializers.py", line 359, in fields
    for key, value in self.get_fields().items():
  File "/Users/b1xpc0/anaconda/envs/bondservice/lib/python3.3/site-packages/rest_framework/serializers.py", line 1000, in get_fields
    field_name, info, model, depth
  File "/Users/b1xpc0/anaconda/envs/bondservice/lib/python3.3/site-packages/rest_framework/serializers.py", line 1135, in build_field
    return self.build_unknown_field(field_name, model_class)
  File "/Users/b1xpc0/anaconda/envs/bondservice/lib/python3.3/site-packages/rest_framework/serializers.py", line 1242, in build_unknown_field
    (field_name, model_class.__name__)
django.core.exceptions.ImproperlyConfigured: Field name `payFrequency` is not valid for model `Bond`.
